Workbook

Sheet Builder
A1: FC Estimate Builder
A2: Procedure | B2: Robotic TKR Unilateral - Right | D2: Pricing Mode | E2: Cash / TR1 | F2: Insurance Org Code
A3: Estimate Pricing | B3: =E2 -> Cash / TR1 | D3: Historical Payer Basis | E3: Auto (Recommended) | F3: Resolved Org Name | G3: =IFERROR(INDEX(Reference!$DV$2:$DV$1000, MATCH(G2, Reference!$DU$2:$DU$1000, 0)), "")
A4: Selected Room Type | B4: Single | D4: Resolved Payor Bucket | E4: =IF(E2="Cash / TR1","Cash",IFERROR(INDEX(Reference!$DT$2:$DT$1000, MATCH(G2, Reference!$DU$2:$DU$1000, 0)), "")) -> Cash | F4: Resolved Tariff Name | G4: =IF(E2="Cash / TR1","KIMS",IFERROR(INDEX(Reference!$DY$2:$DY$1000, MATCH(G2, Reference!$DU$2:$DU$1000, 0)), "")) -> KIMS
A5: Selected Estimate Mode | B5: Typical | D5: Resolved Tariff Code | E5: =IF(E2="Cash / TR1","TR1",IFERROR(INDEX(Reference!$DX$2:$DX$1000, MATCH(G2, Reference!$DU$2:$DU$1000, 0)), "")) -> TR1 | F5: Resolved Pharmacy Basis | G5: =IF(E3<>"Auto (Recommended)",E3,IFERROR(INDEX(Reference!$GP$2:$GP$800, MATCH("pharmacy_basis"&"|"&E4, Reference!$GD$2:$GD$800, 0)), "Cash")) -> Cash
A6: Emergency OT? | B6: No | D6: MLC? | E6: No | F6: Resolved Service Basis | G6: =IF(E3<>"Auto (Recommended)",E3,IFERROR(INDEX(Reference!$GP$2:$GP$800, MATCH("service_basis"&"|"&E4, Reference!$GD$2:$GD$800, 0)), "Cash")) -> Cash
A7: Clinical Drivers | F7: Resolved PF Basis | G7: =IF(E3<>"Auto (Recommended)",E3,IFERROR(INDEX(Reference!$GP$2:$GP$800, MATCH("pf_basis"&"|"&E4, Reference!$GD$2:$GD$800, 0)), "Cash")) -> Cash
A8: Robotic? | B8: Yes | D8: Robotic Charge Presence Rate | E8: 1 | F8: Basis Resolver | G8: =IF(E3<>"Auto (Recommended)","Manual override applied",IFERROR(INDEX(Reference!$GS$2:$GS$800, MATCH("service_basis"&"|"&E4, Reference!$GD$2:$GD$800, 0)), "")) -> Cash selected for service_basis against Cash; recommended exact with 26 cases.
A9: Driver | B9: P25 | C9: P50 | D9: P75 | E9: Selection | F9: Manual Value (used only if Selection = Manual) | G9: Selected Value
A10: LOS | B10: =B11+B12 -> 2 | C10: =C11+C12 -> 3 | D10: =D11+D12 -> 5 | E10: Derived | G10: =G11+G12 -> 3
A11: ICU Days | B11: =INT((IFERROR(INDEX(Reference!$BI$2:$BI$500, MATCH(Builder!G6, Reference!$AZ$2:$AZ$500, 0)), 0)))+IF(MOD((IFERROR(INDEX(Reference!$BI$2:$BI$500, MATCH(Builder!G6, Reference!$AZ$2:$AZ$500, 0)), 0)),1)>0.3,1,0) -> 2 | C11: =INT((IFERROR(INDEX(Reference!$BJ$2:$BJ$500, MATCH(Builder!G6, Reference!$AZ$2:$AZ$500, 0)), 0)))+IF(MOD((IFERROR(INDEX(Reference!$BJ$2:$BJ$500, MATCH(Builder!G6, Reference!$AZ$2:$AZ$500, 0)), 0)),1)>0.3,1,0) -> 2 | D11: =INT((IFERROR(INDEX(Reference!$BK$2:$BK$500, MATCH(Builder!G6, Reference!$AZ$2:$AZ$500, 0)), 0)))+IF(MOD((IFERROR(INDEX(Reference!$BK$2:$BK$500, MATCH(Builder!G6, Reference!$AZ$2:$AZ$500, 0)), 0)),1)>0.3,1,0) -> 3 | E11: P50 | G11: =INT((IF(E11="P25",B11,IF(E11="P50",C11,IF(E11="P75",D11,F11)))))+IF(MOD((IF(E11="P25",B11,IF(E11="P50",C11,IF(E11="P75",D11,F11)))),1)>0.3,1,0) -> 2
A12: Ward Days | B12: =INT((IFERROR(INDEX(Reference!$BL$2:$BL$500, MATCH(Builder!G6, Reference!$AZ$2:$AZ$500, 0)), 0)))+IF(MOD((IFERROR(INDEX(Reference!$BL$2:$BL$500, MATCH(Builder!G6, Reference!$AZ$2:$AZ$500, 0)), 0)),1)>0.3,1,0) -> 0 | C12: =INT((IFERROR(INDEX(Reference!$BM$2:$BM$500, MATCH(Builder!G6, Reference!$AZ$2:$AZ$500, 0)), 0)))+IF(MOD((IFERROR(INDEX(Reference!$BM$2:$BM$500, MATCH(Builder!G6, Reference!$AZ$2:$AZ$500, 0)), 0)),1)>0.3,1,0) -> 1 | D12: =INT((IFERROR(INDEX(Reference!$BN$2:$BN$500, MATCH(Builder!G6, Reference!$AZ$2:$AZ$500, 0)), 0)))+IF(MOD((IFERROR(INDEX(Reference!$BN$2:$BN$500, MATCH(Builder!G6, Reference!$AZ$2:$AZ$500, 0)), 0)),1)>0.3,1,0) -> 2 | E12: P50 | G12: =INT((IF(E12="P25",B12,IF(E12="P50",C12,IF(E12="P75",D12,F12)))))+IF(MOD((IF(E12="P25",B12,IF(E12="P50",C12,IF(E12="P75",D12,F12)))),1)>0.3,1,0) -> 1
A13: OT Hours | B13: =IF((IFERROR(INDEX(Reference!$BO$2:$BO$500, MATCH(Builder!G6, Reference!$AZ$2:$AZ$500, 0)), 0))<=0,0,IF((IFERROR(INDEX(Reference!$BO$2:$BO$500, MATCH(Builder!G6, Reference!$AZ$2:$AZ$500, 0)), 0))<=MIN(Reference!$K$300:$K$331),MIN(Reference!$K$300:$K$331),IF((IFERROR(INDEX(Reference!$BO$2:$BO$500, MATCH(Builder!G6, Reference!$AZ$2:$AZ$500, 0)), 0))>=MAX(Reference!$K$300:$K$331),MAX(Reference!$K$300:$K$331),IF(((IFERROR(INDEX(Reference!$BO$2:$BO$500, MATCH(Builder!G6, Reference!$AZ$2:$AZ$500, 0)), 0))-INDEX(Reference!$K$300:$K$331,MATCH((IFERROR(INDEX(Reference!$BO$2:$BO$500, MATCH(Builder!G6, Reference!$AZ$2:$AZ$500, 0)), 0)),Reference!$K$300:$K$331,1)))<(INDEX(Reference!$K$300:$K$331,MATCH((IFERROR(INDEX(Reference!$BO$2:$BO$500, MATCH(Builder!G6, Reference!$AZ$2:$AZ$500, 0)), 0)),Reference!$K$300:$K$331,1)+1)-(IFERROR(INDEX(Reference!$BO$2:$BO$500, MATCH(Builder!G6, Reference!$AZ$2:$AZ$500, 0)), 0))),INDEX(Reference!$K$300:$K$331,MATCH((IFERROR(INDEX(Reference!$BO$2:$BO$500, MATCH(Builder!G6, Reference!$AZ$2:$AZ$500, 0)), 0)),Reference!$K$300:$K$331,1)),INDEX(Reference!$K$300:$K$331,MATCH((IFERROR(INDEX(Reference!$BO$2:$BO$500, MATCH(Builder!G6, Reference!$AZ$2:$AZ$500, 0)), 0)),Reference!$K$300:$K$331,1)+1))))) -> 2.5 | C13: =IF((IFERROR(INDEX(Reference!$BP$2:$BP$500, MATCH(Builder!G6, Reference!$AZ$2:$AZ$500, 0)), 0))<=0,0,IF((IFERROR(INDEX(Reference!$BP$2:$BP$500, MATCH(Builder!G6, Reference!$AZ$2:$AZ$500, 0)), 0))<=MIN(Reference!$K$300:$K$331),MIN(Reference!$K$300:$K$331),IF((IFERROR(INDEX(Reference!$BP$2:$BP$500, MATCH(Builder!G6, Reference!$AZ$2:$AZ$500, 0)), 0))>=MAX(Reference!$K$300:$K$331),MAX(Reference!$K$300:$K$331),IF(((IFERROR(INDEX(Reference!$BP$2:$BP$500, MATCH(Builder!G6, Reference!$AZ$2:$AZ$500, 0)), 0))-INDEX(Reference!$K$300:$K$331,MATCH((IFERROR(INDEX(Reference!$BP$2:$BP$500, MATCH(Builder!G6, Reference!$AZ$2:$AZ$500, 0)), 0)),Reference!$K$300:$K$331,1)))<(INDEX(Reference!$K$300:$K$331,MATCH((IFERROR(INDEX(Reference!$BP$2:$BP$500, MATCH(Builder!G6, Reference!$AZ$2:$AZ$500, 0)), 0)),Reference!$K$300:$K$331,1)+1)-(IFERROR(INDEX(Reference!$BP$2:$BP$500, MATCH(Builder!G6, Reference!$AZ$2:$AZ$500, 0)), 0))),INDEX(Reference!$K$300:$K$331,MATCH((IFERROR(INDEX(Reference!$BP$2:$BP$500, MATCH(Builder!G6, Reference!$AZ$2:$AZ$500, 0)), 0)),Reference!$K$300:$K$331,1)),INDEX(Reference!$K$300:$K$331,MATCH((IFERROR(INDEX(Reference!$BP$2:$BP$500, MATCH(Builder!G6, Reference!$AZ$2:$AZ$500, 0)), 0)),Reference!$K$300:$K$331,1)+1))))) -> 3 | D13: =IF((IFERROR(INDEX(Reference!$BQ$2:$BQ$500, MATCH(Builder!G6, Reference!$AZ$2:$AZ$500, 0)), 0))<=0,0,IF((IFERROR(INDEX(Reference!$BQ$2:$BQ$500, MATCH(Builder!G6, Reference!$AZ$2:$AZ$500, 0)), 0))<=MIN(Reference!$K$300:$K$331),MIN(Reference!$K$300:$K$331),IF((IFERROR(INDEX(Reference!$BQ$2:$BQ$500, MATCH(Builder!G6, Reference!$AZ$2:$AZ$500, 0)), 0))>=MAX(Reference!$K$300:$K$331),MAX(Reference!$K$300:$K$331),IF(((IFERROR(INDEX(Reference!$BQ$2:$BQ$500, MATCH(Builder!G6, Reference!$AZ$2:$AZ$500, 0)), 0))-INDEX(Reference!$K$300:$K$331,MATCH((IFERROR(INDEX(Reference!$BQ$2:$BQ$500, MATCH(Builder!G6, Reference!$AZ$2:$AZ$500, 0)), 0)),Reference!$K$300:$K$331,1)))<(INDEX(Reference!$K$300:$K$331,MATCH((IFERROR(INDEX(Reference!$BQ$2:$BQ$500, MATCH(Builder!G6, Reference!$AZ$2:$AZ$500, 0)), 0)),Reference!$K$300:$K$331,1)+1)-(IFERROR(INDEX(Reference!$BQ$2:$BQ$500, MATCH(Builder!G6, Reference!$AZ$2:$AZ$500, 0)), 0))),INDEX(Reference!$K$300:$K$331,MATCH((IFERROR(INDEX(Reference!$BQ$2:$BQ$500, MATCH(Builder!G6, Reference!$AZ$2:$AZ$500, 0)), 0)),Reference!$K$300:$K$331,1)),INDEX(Reference!$K$300:$K$331,MATCH((IFERROR(INDEX(Reference!$BQ$2:$BQ$500, MATCH(Builder!G6, Reference!$AZ$2:$AZ$500, 0)), 0)),Reference!$K$300:$K$331,1)+1))))) -> 3 | E13: P50 | G13: =IF((IF(E13="P25",B13,IF(E13="P50",C13,IF(E13="P75",D13,F13))))<=0,0,IF((IF(E13="P25",B13,IF(E13="P50",C13,IF(E13="P75",D13,F13))))<=MIN(Reference!$K$300:$K$331),MIN(Reference!$K$300:$K$331),IF((IF(E13="P25",B13,IF(E13="P50",C13,IF(E13="P75",D13,F13))))>=MAX(Reference!$K$300:$K$331),MAX(Reference!$K$300:$K$331),IF(((IF(E13="P25",B13,IF(E13="P50",C13,IF(E13="P75",D13,F13))))-INDEX(Reference!$K$300:$K$331,MATCH((IF(E13="P25",B13,IF(E13="P50",C13,IF(E13="P75",D13,F13)))),Reference!$K$300:$K$331,1)))<(INDEX(Reference!$K$300:$K$331,MATCH((IF(E13="P25",B13,IF(E13="P50",C13,IF(E13="P75",D13,F13)))),Reference!$K$300:$K$331,1)+1)-(IF(E13="P25",B13,IF(E13="P50",C13,IF(E13="P75",D13,F13))))),INDEX(Reference!$K$300:$K$331,MATCH((IF(E13="P25",B13,IF(E13="P50",C13,IF(E13="P75",D13,F13)))),Reference!$K$300:$K$331,1)),INDEX(Reference!$K$300:$K$331,MATCH((IF(E13="P25",B13,IF(E13="P50",C13,IF(E13="P75",D13,F13)))),Reference!$K$300:$K$331,1)+1))))) -> 3
A14: Resolved OT Slot (Hours) | B14: =IF((G13)<=0,"",IF((G13)<=0,0,IF((G13)<=MIN(Reference!$K$300:$K$331),MIN(Reference!$K$300:$K$331),IF((G13)>=MAX(Reference!$K$300:$K$331),MAX(Reference!$K$300:$K$331),IF(((G13)-INDEX(Reference!$K$300:$K$331,MATCH((G13),Reference!$K$300:$K$331,1)))<(INDEX(Reference!$K$300:$K$331,MATCH((G13),Reference!$K$300:$K$331,1)+1)-(G13)),INDEX(Reference!$K$300:$K$331,MATCH((G13),Reference!$K$300:$K$331,1)),INDEX(Reference!$K$300:$K$331,MATCH((G13),Reference!$K$300:$K$331,1)+1)))))) -> 3
A15: Resolved OT Slot Code | B15: =IF(B14="","",IFERROR(INDEX(Reference!$EQ$2:$EQ$1000,MATCH(Builder!E5&"|"&IF(B6="Yes","emergency","normal")&"|"&(B14),Reference!$EL$2:$EL$1000,0)),"")) -> OTC0010
A16: Resolved OT Slot Label | B16: =IF(B14="","",IFERROR(INDEX(Reference!$ER$2:$ER$1000,MATCH(Builder!E5&"|"&IF(B6="Yes","emergency","normal")&"|"&(B14),Reference!$EL$2:$EL$1000,0)),"")) -> OT - 3 HOURS
A17: Resolved OT Type | B17: =IF(B6="Yes","Emergency","Normal") -> Normal
A19: How To Use
A20: 1. Cash mode uses TR1 pricing. Insurance mode uses the tariff code resolved from the selected insurance organization.
A21: 2. Historical Payer Basis can stay on Auto to resolve service, pharmacy, and PF reference cohorts separately, or be manually overridden for all three together.
A22: 3. LOS is always derived as ICU Days + Ward Days. Manual Value is used only for ICU Days, Ward Days, or OT Hours when that row's Selection is set to Manual.
A23: 4. Estimate Mode changes the amount band used downstream: Low = P25, Typical = P50, High = P75 for each eligible line item.
A24: 5. OT pricing uses the nearest supported tariff OT slot from the selected OT duration and Emergency OT setting.
A25: 6. Drug administration and insurance-excluded service items are automatically suppressed in insurance mode. Package details and patient-policy coverage are not applied in this workbook yet.
A26: 7. Robotic charge is controlled from the Builder. When Robotic is Yes, all mapped robotic-charge rows are included; when No, they are fully excluded.
A27: 8. MLC adds one tariff-backed MLC charge only when the MLC input is Yes. Use Advanced Controls, Implant Selection, Service Add-Ons, and Grouped Adjustments only when the default estimate needs refinement.
A28: 9. Read the final estimate and bucket summary on Estimate Summary.

Sheet Estimate Summary
A1: Estimate Summary
A2: Selected Room | B2: =Builder!B4 -> Single | D2: Final Estimate | E2: =IF(B2="General",'Line Item Detail'!W75,IF(B2="Twin",'Line Item Detail'!X75,'Line Item Detail'!Y75)) -> 597612.07
A3: Selected Estimate Mode | B3: =Builder!B5 -> Typical | D3: How estimate mode works | E3: Low uses P25 amounts, Typical uses P50, and High uses P75. Driver rows change only if their own Selection or Manual value changes. OT uses the resolved tariff OT slot from the selected OT duration and Emergency OT setting. Insurance mode prices services from the selected org tariff and suppresses insurance-excluded rows.
A4: Historical Payer Basis | B4: =Builder!E3 -> Auto (Recommended)
A5: Pricing Mode | B5: =Builder!E2 -> Cash / TR1
A6: Insurance Org Code | B6: =Builder!G2 -> 0 | D6: Room | E6: Low | F6: Typical | G6: High | I6: Selected Drivers & Controls | L6: Cohort Basis Counts
A7: Resolved Payor Bucket | B7: =Builder!E4 -> Cash | D7: General | E7: ='Line Item Detail'!N75 -> 555166.73 | F7: ='Line Item Detail'!O75 -> 579449.25 | G7: ='Line Item Detail'!P75 -> 685465.15 | I7: Selected LOS | J7: =Builder!G10 -> 3 | L7: Selected Cohort Size | M7: =IFERROR(INDEX(Reference!$BA$2:$BA$500, MATCH(Builder!G6, Reference!$AZ$2:$AZ$500, 0)), 0) -> 26
A8: Resolved Tariff Code | B8: =Builder!E5 -> TR1 | D8: Twin | E8: ='Line Item Detail'!Q75 -> 561243.76 | F8: ='Line Item Detail'!R75 -> 587765.91 | G8: ='Line Item Detail'!S75 -> 696021.43 | I8: Selected ICU Days | J8: =Builder!G11 -> 2 | L8: Cash Count | M8: =IFERROR(INDEX(Reference!$BB$2:$BB$500, MATCH(Builder!G6, Reference!$AZ$2:$AZ$500, 0)), 0) -> 26
A9: Pharmacy Benchmark Basis | B9: =Builder!G5 -> Cash | D9: Single | E9: ='Line Item Detail'!T75 -> 566487.76 | F9: ='Line Item Detail'!U75 -> 597612.07 | G9: ='Line Item Detail'!V75 -> 710469.74 | I9: Selected Ward Days | J9: =Builder!G12 -> 1 | L9: GIPSA Count | M9: =IFERROR(INDEX(Reference!$BC$2:$BC$500, MATCH(Builder!G6, Reference!$AZ$2:$AZ$500, 0)), 0) -> 0
A10: Resolved Service Basis | B10: =Builder!G6 -> Cash | I10: Selected OT Hours | J10: =Builder!G13 -> 3 | L10: Non-GIPSA Count | M10: =IFERROR(INDEX(Reference!$BD$2:$BD$500, MATCH(Builder!G6, Reference!$AZ$2:$AZ$500, 0)), 0) -> 0
A11: Resolved PF Basis | B11: =Builder!G7 -> Cash | I11: Emergency OT? | J11: =Builder!B6 -> No | L11: Corporate Count | M11: =IFERROR(INDEX(Reference!$BE$2:$BE$500, MATCH(Builder!G6, Reference!$AZ$2:$AZ$500, 0)), 0) -> 0
A12: Bucket | B12: Selected Estimate | I12: Resolved OT Slot Hours | J12: =Builder!B14 -> 3
A13: Room Charges | B13: =IF(B2="General",SUMIF('Line Item Detail'!$B$2:$B$73,A13,'Line Item Detail'!$W$2:$W$73),IF(B2="Twin",SUMIF('Line Item Detail'!$B$2:$B$73,A13,'Line Item Detail'!$X$2:$X$73),SUMIF('Line Item Detail'!$B$2:$B$73,A13,'Line Item Detail'!$Y$2:$Y$73))) -> 45280 | I13: Resolved OT Slot Code | J13: =Builder!B15 -> OTC0010 | L13: Pharmacy P50 by Basis
A14: Investigations | B14: =IF(B2="General",SUMIF('Line Item Detail'!$B$2:$B$73,A14,'Line Item Detail'!$W$2:$W$73),IF(B2="Twin",SUMIF('Line Item Detail'!$B$2:$B$73,A14,'Line Item Detail'!$X$2:$X$73),SUMIF('Line Item Detail'!$B$2:$B$73,A14,'Line Item Detail'!$Y$2:$Y$73))) -> 14940 | I14: Resolved OT Type | J14: =Builder!B17 -> Normal | L14: Bucket | M14: Cash | N14: GIPSA | O14: Non-GIPSA | P14: Corporate | Q14: Insurance All | R14: All Payers
A15: Procedure / OT Charges | B15: =IF(B2="General",SUMIF('Line Item Detail'!$B$2:$B$73,A15,'Line Item Detail'!$W$2:$W$73),IF(B2="Twin",SUMIF('Line Item Detail'!$B$2:$B$73,A15,'Line Item Detail'!$X$2:$X$73),SUMIF('Line Item Detail'!$B$2:$B$73,A15,'Line Item Detail'!$Y$2:$Y$73))) -> 158660 | I15: MLC? | J15: =Builder!E6 -> No | L15: IP Drugs / Day | M15: =IFERROR(INDEX(Reference!$CK$2:$CK$500, MATCH("Cash", Reference!$AZ$2:$AZ$500, 0)), 0) -> 2855.3187 | N15: =IFERROR(INDEX(Reference!$CK$2:$CK$500, MATCH("GIPSA Insurance", Reference!$AZ$2:$AZ$500, 0)), 0) -> 0 | O15: =IFERROR(INDEX(Reference!$CK$2:$CK$500, MATCH("Non-GIPSA Insurance", Reference!$AZ$2:$AZ$500, 0)), 0) -> 0 | P15: =IFERROR(INDEX(Reference!$CK$2:$CK$500, MATCH("Corporate", Reference!$AZ$2:$AZ$500, 0)), 0) -> 0 | Q15: =IFERROR(INDEX(Reference!$CK$2:$CK$500, MATCH("Insurance All", Reference!$AZ$2:$AZ$500, 0)), 0) -> 0 | R15: =IFERROR(INDEX(Reference!$CK$2:$CK$500, MATCH("All Payers", Reference!$AZ$2:$AZ$500, 0)), 0) -> 2855.3187
A16: Bedside Services | B16: =IF(B2="General",SUMIF('Line Item Detail'!$B$2:$B$73,A16,'Line Item Detail'!$W$2:$W$73),IF(B2="Twin",SUMIF('Line Item Detail'!$B$2:$B$73,A16,'Line Item Detail'!$X$2:$X$73),SUMIF('Line Item Detail'!$B$2:$B$73,A16,'Line Item Detail'!$Y$2:$Y$73))) -> 5200 | I16: OT Consumables Selected Typical | J16: ='Advanced Controls'!C6 -> 72382.9 | L16: IP Consumables / Day | M16: =IFERROR(INDEX(Reference!$CN$2:$CN$500, MATCH("Cash", Reference!$AZ$2:$AZ$500, 0)), 0) -> 3428.8283 | N16: =IFERROR(INDEX(Reference!$CN$2:$CN$500, MATCH("GIPSA Insurance", Reference!$AZ$2:$AZ$500, 0)), 0) -> 0 | O16: =IFERROR(INDEX(Reference!$CN$2:$CN$500, MATCH("Non-GIPSA Insurance", Reference!$AZ$2:$AZ$500, 0)), 0) -> 0 | P16: =IFERROR(INDEX(Reference!$CN$2:$CN$500, MATCH("Corporate", Reference!$AZ$2:$AZ$500, 0)), 0) -> 0 | Q16: =IFERROR(INDEX(Reference!$CN$2:$CN$500, MATCH("Insurance All", Reference!$AZ$2:$AZ$500, 0)), 0) -> 0 | R16: =IFERROR(INDEX(Reference!$CN$2:$CN$500, MATCH("All Payers", Reference!$AZ$2:$AZ$500, 0)), 0) -> 3428.8283
A17: Pharmacy | B17: =IF(B2="General",SUMIF('Line Item Detail'!$B$2:$B$73,A17,'Line Item Detail'!$W$2:$W$73),IF(B2="Twin",SUMIF('Line Item Detail'!$B$2:$B$73,A17,'Line Item Detail'!$X$2:$X$73),SUMIF('Line Item Detail'!$B$2:$B$73,A17,'Line Item Detail'!$Y$2:$Y$73))) -> 189805.04 | I17: Implants Selected Typical | J17: ='Implant Selection'!F6 -> 89130.16 | L17: OT Drugs | M17: =IFERROR(INDEX(Reference!$CB$2:$CB$500, MATCH("Cash", Reference!$AZ$2:$AZ$500, 0)), 0) -> 9439.535 | N17: =IFERROR(INDEX(Reference!$CB$2:$CB$500, MATCH("GIPSA Insurance", Reference!$AZ$2:$AZ$500, 0)), 0) -> 0 | O17: =IFERROR(INDEX(Reference!$CB$2:$CB$500, MATCH("Non-GIPSA Insurance", Reference!$AZ$2:$AZ$500, 0)), 0) -> 0 | P17: =IFERROR(INDEX(Reference!$CB$2:$CB$500, MATCH("Corporate", Reference!$AZ$2:$AZ$500, 0)), 0) -> 0 | Q17: =IFERROR(INDEX(Reference!$CB$2:$CB$500, MATCH("Insurance All", Reference!$AZ$2:$AZ$500, 0)), 0) -> 0 | R17: =IFERROR(INDEX(Reference!$CB$2:$CB$500, MATCH("All Payers", Reference!$AZ$2:$AZ$500, 0)), 0) -> 9439.535
A18: Drug Administration Charges | B18: =IF(B2="General",SUMIF('Line Item Detail'!$B$2:$B$73,A18,'Line Item Detail'!$W$2:$W$73),IF(B2="Twin",SUMIF('Line Item Detail'!$B$2:$B$73,A18,'Line Item Detail'!$X$2:$X$73),SUMIF('Line Item Detail'!$B$2:$B$73,A18,'Line Item Detail'!$Y$2:$Y$73))) -> 23725.63 | I18: Optional Add-Ons Selected Typical | J18: ='Service Add-Ons'!C5 -> 0 | L18: OT Consumables | M18: =IFERROR(INDEX(Reference!$CE$2:$CE$500, MATCH("Cash", Reference!$AZ$2:$AZ$500, 0)), 0) -> 72382.9 | N18: =IFERROR(INDEX(Reference!$CE$2:$CE$500, MATCH("GIPSA Insurance", Reference!$AZ$2:$AZ$500, 0)), 0) -> 0 | O18: =IFERROR(INDEX(Reference!$CE$2:$CE$500, MATCH("Non-GIPSA Insurance", Reference!$AZ$2:$AZ$500, 0)), 0) -> 0 | P18: =IFERROR(INDEX(Reference!$CE$2:$CE$500, MATCH("Corporate", Reference!$AZ$2:$AZ$500, 0)), 0) -> 0 | Q18: =IFERROR(INDEX(Reference!$CE$2:$CE$500, MATCH("Insurance All", Reference!$AZ$2:$AZ$500, 0)), 0) -> 0 | R18: =IFERROR(INDEX(Reference!$CE$2:$CE$500, MATCH("All Payers", Reference!$AZ$2:$AZ$500, 0)), 0) -> 72382.9
A19: Professional Fees | B19: =IF(B2="General",SUMIF('Line Item Detail'!$B$2:$B$73,A19,'Line Item Detail'!$W$2:$W$73),IF(B2="Twin",SUMIF('Line Item Detail'!$B$2:$B$73,A19,'Line Item Detail'!$X$2:$X$73),SUMIF('Line Item Detail'!$B$2:$B$73,A19,'Line Item Detail'!$Y$2:$Y$73))) -> 160001.4 | I19: Grouped Adjustments Selected Typical | J19: ='Grouped Adjustments'!C5 -> 7280 | L19: Implants | M19: =IFERROR(INDEX(Reference!$CH$2:$CH$500, MATCH("Cash", Reference!$AZ$2:$AZ$500, 0)), 0) -> 89130.16 | N19: =IFERROR(INDEX(Reference!$CH$2:$CH$500, MATCH("GIPSA Insurance", Reference!$AZ$2:$AZ$500, 0)), 0) -> 0 | O19: =IFERROR(INDEX(Reference!$CH$2:$CH$500, MATCH("Non-GIPSA Insurance", Reference!$AZ$2:$AZ$500, 0)), 0) -> 0 | P19: =IFERROR(INDEX(Reference!$CH$2:$CH$500, MATCH("Corporate", Reference!$AZ$2:$AZ$500, 0)), 0) -> 0 | Q19: =IFERROR(INDEX(Reference!$CH$2:$CH$500, MATCH("Insurance All", Reference!$AZ$2:$AZ$500, 0)), 0) -> 0 | R19: =IFERROR(INDEX(Reference!$CH$2:$CH$500, MATCH("All Payers", Reference!$AZ$2:$AZ$500, 0)), 0) -> 89130.16
A20: Optional Add-Ons | B20: =IF(B2="General",SUMIF('Line Item Detail'!$B$2:$B$73,A20,'Line Item Detail'!$W$2:$W$73),IF(B2="Twin",SUMIF('Line Item Detail'!$B$2:$B$73,A20,'Line Item Detail'!$X$2:$X$73),SUMIF('Line Item Detail'!$B$2:$B$73,A20,'Line Item Detail'!$Y$2:$Y$73))) -> 0 | I20: Grouped Adjustments Included Count | J20: ='Grouped Adjustments'!E5 -> 3
A21: Grand Total | B21: =E2 -> 597612.07
A22: Professional Fees (Historic Basis P50) | B22: =IFERROR(INDEX(Reference!$FF$2:$FF$500, MATCH(Builder!G7, Reference!$FC$2:$FC$500, 0)), 0) -> 98192
A23: Grand Total (Historic PF) | B23: =B21-B19+B22 -> 535802.67
I24: Service Count Check | L24: Selected Basis PF Mix
A25: Professional Fees by Payer | I25: Current Included | J25: ='Service Add-Ons'!P10 -> 37 | L25: PF Bucket | M25: P25 | N25: P50 | O25: P75 | P25: Note
A26: Payer | B26: Cases | C26: P25 | D26: P50 | E26: P75 | I26: Historical P25 | J26: ='Service Add-Ons'!P5 -> 36.25 | L26: Collectible Historical PF | M26: =IFERROR(INDEX(Reference!$FE$2:$FE$500, MATCH(Builder!G7, Reference!$FC$2:$FC$500, 0)), 0) -> 96442 | N26: =IFERROR(INDEX(Reference!$FF$2:$FF$500, MATCH(Builder!G7, Reference!$FC$2:$FC$500, 0)), 0) -> 98192 | O26: =IFERROR(INDEX(Reference!$FG$2:$FG$500, MATCH(Builder!G7, Reference!$FC$2:$FC$500, 0)), 0) -> 99817 | P26: Total collectible PF
A27: Cash | B27: =IFERROR(INDEX(Reference!$FD$2:$FD$500, MATCH("Cash", Reference!$FC$2:$FC$500, 0)), 0) -> 26 | C27: =IFERROR(INDEX(Reference!$FE$2:$FE$500, MATCH("Cash", Reference!$FC$2:$FC$500, 0)), 0) -> 96442 | D27: =IFERROR(INDEX(Reference!$FF$2:$FF$500, MATCH("Cash", Reference!$FC$2:$FC$500, 0)), 0) -> 98192 | E27: =IFERROR(INDEX(Reference!$FG$2:$FG$500, MATCH("Cash", Reference!$FC$2:$FC$500, 0)), 0) -> 99817 | I27: Historical P50 | J27: ='Service Add-Ons'!P6 -> 39 | L27: Named PF | M27: =IFERROR(INDEX(Reference!$FH$2:$FH$500, MATCH(Builder!G7, Reference!$FC$2:$FC$500, 0)), 0) -> 95562 | N27: =IFERROR(INDEX(Reference!$FI$2:$FI$500, MATCH(Builder!G7, Reference!$FC$2:$FC$500, 0)), 0) -> 97062 | O27: =IFERROR(INDEX(Reference!$FJ$2:$FJ$500, MATCH(Builder!G7, Reference!$FC$2:$FC$500, 0)), 0) -> 98562 | P27: Named doctor rows
A28: GIPSA Insurance | B28: =IFERROR(INDEX(Reference!$FD$2:$FD$500, MATCH("GIPSA Insurance", Reference!$FC$2:$FC$500, 0)), 0) -> 0 | C28: =IFERROR(INDEX(Reference!$FE$2:$FE$500, MATCH("GIPSA Insurance", Reference!$FC$2:$FC$500, 0)), 0) -> 0 | D28: =IFERROR(INDEX(Reference!$FF$2:$FF$500, MATCH("GIPSA Insurance", Reference!$FC$2:$FC$500, 0)), 0) -> 0 | E28: =IFERROR(INDEX(Reference!$FG$2:$FG$500, MATCH("GIPSA Insurance", Reference!$FC$2:$FC$500, 0)), 0) -> 0 | I28: Historical P75 | J28: ='Service Add-Ons'!P7 -> 41 | L28: General Needed PF | M28: =IFERROR(INDEX(Reference!$FK$2:$FK$500, MATCH(Builder!G7, Reference!$FC$2:$FC$500, 0)), 0) -> 880 | N28: =IFERROR(INDEX(Reference!$FL$2:$FL$500, MATCH(Builder!G7, Reference!$FC$2:$FC$500, 0)), 0) -> 880 | O28: =IFERROR(INDEX(Reference!$FM$2:$FM$500, MATCH(Builder!G7, Reference!$FC$2:$FC$500, 0)), 0) -> 880 | P28: General-needed rows
A29: Non-GIPSA Insurance | B29: =IFERROR(INDEX(Reference!$FD$2:$FD$500, MATCH("Non-GIPSA Insurance", Reference!$FC$2:$FC$500, 0)), 0) -> 0 | C29: =IFERROR(INDEX(Reference!$FE$2:$FE$500, MATCH("Non-GIPSA Insurance", Reference!$FC$2:$FC$500, 0)), 0) -> 0 | D29: =IFERROR(INDEX(Reference!$FF$2:$FF$500, MATCH("Non-GIPSA Insurance", Reference!$FC$2:$FC$500, 0)), 0) -> 0 | E29: =IFERROR(INDEX(Reference!$FG$2:$FG$500, MATCH("Non-GIPSA Insurance", Reference!$FC$2:$FC$500, 0)), 0) -> 0 | I29: Alert | J29: ='Service Add-Ons'!P11 -> Within historical range | L29: Surgeon Named | M29: =IFERROR(INDEX(Reference!$FN$2:$FN$500, MATCH(Builder!G7, Reference!$FC$2:$FC$500, 0)), 0) -> 65000 | N29: =IFERROR(INDEX(Reference!$FO$2:$FO$500, MATCH(Builder!G7, Reference!$FC$2:$FC$500, 0)), 0) -> 65000 | O29: =IFERROR(INDEX(Reference!$FP$2:$FP$500, MATCH(Builder!G7, Reference!$FC$2:$FC$500, 0)), 0) -> 65000 | P29: Named surgeon rows
A30: Corporate | B30: =IFERROR(INDEX(Reference!$FD$2:$FD$500, MATCH("Corporate", Reference!$FC$2:$FC$500, 0)), 0) -> 0 | C30: =IFERROR(INDEX(Reference!$FE$2:$FE$500, MATCH("Corporate", Reference!$FC$2:$FC$500, 0)), 0) -> 0 | D30: =IFERROR(INDEX(Reference!$FF$2:$FF$500, MATCH("Corporate", Reference!$FC$2:$FC$500, 0)), 0) -> 0 | E30: =IFERROR(INDEX(Reference!$FG$2:$FG$500, MATCH("Corporate", Reference!$FC$2:$FC$500, 0)), 0) -> 0 | L30: Assistant Surgeon Named | M30: =IFERROR(INDEX(Reference!$FQ$2:$FQ$500, MATCH(Builder!G7, Reference!$FC$2:$FC$500, 0)), 0) -> 9750 | N30: =IFERROR(INDEX(Reference!$FR$2:$FR$500, MATCH(Builder!G7, Reference!$FC$2:$FC$500, 0)), 0) -> 9750 | O30: =IFERROR(INDEX(Reference!$FS$2:$FS$500, MATCH(Builder!G7, Reference!$FC$2:$FC$500, 0)), 0) -> 9750 | P30: Named assistant surgeon rows
A31: Insurance All | B31: =IFERROR(INDEX(Reference!$FD$2:$FD$500, MATCH("Insurance All", Reference!$FC$2:$FC$500, 0)), 0) -> 0 | C31: =IFERROR(INDEX(Reference!$FE$2:$FE$500, MATCH("Insurance All", Reference!$FC$2:$FC$500, 0)), 0) -> 0 | D31: =IFERROR(INDEX(Reference!$FF$2:$FF$500, MATCH("Insurance All", Reference!$FC$2:$FC$500, 0)), 0) -> 0 | E31: =IFERROR(INDEX(Reference!$FG$2:$FG$500, MATCH("Insurance All", Reference!$FC$2:$FC$500, 0)), 0) -> 0 | L31: Anesthetist Named | M31: =IFERROR(INDEX(Reference!$FT$2:$FT$500, MATCH(Builder!G7, Reference!$FC$2:$FC$500, 0)), 0) -> 16750 | N31: =IFERROR(INDEX(Reference!$FU$2:$FU$500, MATCH(Builder!G7, Reference!$FC$2:$FC$500, 0)), 0) -> 16750 | O31: =IFERROR(INDEX(Reference!$FV$2:$FV$500, MATCH(Builder!G7, Reference!$FC$2:$FC$500, 0)), 0) -> 16750 | P31: Named anesthetist rows
A32: All Payers | B32: =IFERROR(INDEX(Reference!$FD$2:$FD$500, MATCH("All Payers", Reference!$FC$2:$FC$500, 0)), 0) -> 26 | C32: =IFERROR(INDEX(Reference!$FE$2:$FE$500, MATCH("All Payers", Reference!$FC$2:$FC$500, 0)), 0) -> 96442 | D32: =IFERROR(INDEX(Reference!$FF$2:$FF$500, MATCH("All Payers", Reference!$FC$2:$FC$500, 0)), 0) -> 98192 | E32: =IFERROR(INDEX(Reference!$FG$2:$FG$500, MATCH("All Payers", Reference!$FC$2:$FC$500, 0)), 0) -> 99817 | L32: Assistant Anesthetist Named | M32: =IFERROR(INDEX(Reference!$FW$2:$FW$500, MATCH(Builder!G7, Reference!$FC$2:$FC$500, 0)), 0) -> 4062 | N32: =IFERROR(INDEX(Reference!$FX$2:$FX$500, MATCH(Builder!G7, Reference!$FC$2:$FC$500, 0)), 0) -> 4062 | O32: =IFERROR(INDEX(Reference!$FY$2:$FY$500, MATCH(Builder!G7, Reference!$FC$2:$FC$500, 0)), 0) -> 4062 | P32: Named assistant anesthetist rows
L33: Consultant / Physician Named | M33: =IFERROR(INDEX(Reference!$FZ$2:$FZ$500, MATCH(Builder!G7, Reference!$FC$2:$FC$500, 0)), 0) -> 0 | N33: =IFERROR(INDEX(Reference!$GA$2:$GA$500, MATCH(Builder!G7, Reference!$FC$2:$FC$500, 0)), 0) -> 1500 | O33: =IFERROR(INDEX(Reference!$GB$2:$GB$500, MATCH(Builder!G7, Reference!$FC$2:$FC$500, 0)), 0) -> 3000 | P33: Named consultant/physician rows
L34: Selected Basis PF Shape | M34: =IFERROR(INDEX(Reference!$GC$2:$GC$500, MATCH(Builder!G7, Reference!$FC$2:$FC$500, 0)), "") -> cash_formula_like
A36: IP FC Actuals Selected-Basis Snapshot
A37: Field | B37: Basis | C37: P25 | D37: P50 | E37: P75 | F37: Notes
A38: LOS Days | B38: =Builder!G6 -> Cash | C38: =IFERROR(INDEX(Reference!$HH$2:$HH$1000, MATCH(Builder!G6&"|"&"los_days", Reference!$HA$2:$HA$1000, 0)), 0) -> 3 | D38: =IFERROR(INDEX(Reference!$HI$2:$HI$1000, MATCH(Builder!G6&"|"&"los_days", Reference!$HA$2:$HA$1000, 0)), 0) -> 3 | E38: =IFERROR(INDEX(Reference!$HJ$2:$HJ$1000, MATCH(Builder!G6&"|"&"los_days", Reference!$HA$2:$HA$1000, 0)), 0) -> 3.75
A39: ICU Days | B39: =Builder!G6 -> Cash | C39: =IFERROR(INDEX(Reference!$HH$2:$HH$1000, MATCH(Builder!G6&"|"&"icu_days", Reference!$HA$2:$HA$1000, 0)), 0) -> 2 | D39: =IFERROR(INDEX(Reference!$HI$2:$HI$1000, MATCH(Builder!G6&"|"&"icu_days", Reference!$HA$2:$HA$1000, 0)), 0) -> 2 | E39: =IFERROR(INDEX(Reference!$HJ$2:$HJ$1000, MATCH(Builder!G6&"|"&"icu_days", Reference!$HA$2:$HA$1000, 0)), 0) -> 3
A40: Ward Days | B40: =Builder!G6 -> Cash | C40: =IFERROR(INDEX(Reference!$HH$2:$HH$1000, MATCH(Builder!G6&"|"&"ward_days", Reference!$HA$2:$HA$1000, 0)), 0) -> 0.25 | D40: =IFERROR(INDEX(Reference!$HI$2:$HI$1000, MATCH(Builder!G6&"|"&"ward_days", Reference!$HA$2:$HA$1000, 0)), 0) -> 1 | E40: =IFERROR(INDEX(Reference!$HJ$2:$HJ$1000, MATCH(Builder!G6&"|"&"ward_days", Reference!$HA$2:$HA$1000, 0)), 0) -> 1.75
A41: OT Hours | B41: =Builder!G6 -> Cash | C41: =IFERROR(INDEX(Reference!$HH$2:$HH$1000, MATCH(Builder!G6&"|"&"ot_hours", Reference!$HA$2:$HA$1000, 0)), 0) -> 2.5 | D41: =IFERROR(INDEX(Reference!$HI$2:$HI$1000, MATCH(Builder!G6&"|"&"ot_hours", Reference!$HA$2:$HA$1000, 0)), 0) -> 3 | E41: =IFERROR(INDEX(Reference!$HJ$2:$HJ$1000, MATCH(Builder!G6&"|"&"ot_hours", Reference!$HA$2:$HA$1000, 0)), 0) -> 3
...

Sheet Estimate vs IP FC Actuals
A1: Estimate vs IP FC Actuals
A2: Compares the current estimate against basis-aligned historical actuals. Service buckets use the resolved service basis, pharmacy and drug administration use the resolved pharmacy basis, and professional fees use the resolved PF basis.
A4: Metric | B4: Comparison Basis | C4: Selected Estimate | D4: Actual P25 | E4: Actual P50 | F4: Actual P75 | G4: Delta vs P25 | H4: Delta vs P50 | I4: Delta vs P75 | J4: Status
A5: Room Charges | B5: =Builder!G6 -> Cash | C5: ='Estimate Summary'!B13 -> 45280 | D5: =IFERROR(INDEX(Reference!$HH$2:$HH$1000, MATCH(Builder!G6&"|"&"room_charges", Reference!$HA$2:$HA$1000, 0)), 0) -> 41910 | E5: =IFERROR(INDEX(Reference!$HI$2:$HI$1000, MATCH(Builder!G6&"|"&"room_charges", Reference!$HA$2:$HA$1000, 0)), 0) -> 45064 | F5: =IFERROR(INDEX(Reference!$HJ$2:$HJ$1000, MATCH(Builder!G6&"|"&"room_charges", Reference!$HA$2:$HA$1000, 0)), 0) -> 54051 | G5: =C5-D5 -> 3370 | H5: =C5-E5 -> 216 | I5: =C5-F5 -> -8771 | J5: =IF(AND(OR(C5<D5,C5>F5),ABS(H5)>MAX(5000,0.2*MAX(E5,1))),"Material Gap",IF(C5<D5,"Below Range",IF(C5>F5,"Above Range","Within Range"))) -> Within Range
A6: Investigations | B6: =Builder!G6 -> Cash | C6: ='Estimate Summary'!B14 -> 14940 | D6: =IFERROR(INDEX(Reference!$HH$2:$HH$1000, MATCH(Builder!G6&"|"&"investigations", Reference!$HA$2:$HA$1000, 0)), 0) -> 9027.5 | E6: =IFERROR(INDEX(Reference!$HI$2:$HI$1000, MATCH(Builder!G6&"|"&"investigations", Reference!$HA$2:$HA$1000, 0)), 0) -> 15370 | F6: =IFERROR(INDEX(Reference!$HJ$2:$HJ$1000, MATCH(Builder!G6&"|"&"investigations", Reference!$HA$2:$HA$1000, 0)), 0) -> 18402.5 | G6: =C6-D6 -> 5912.5 | H6: =C6-E6 -> -430 | I6: =C6-F6 -> -3462.5 | J6: =IF(AND(OR(C6<D6,C6>F6),ABS(H6)>MAX(5000,0.2*MAX(E6,1))),"Material Gap",IF(C6<D6,"Below Range",IF(C6>F6,"Above Range","Within Range"))) -> Within Range
A7: Procedure / OT Charges | B7: =Builder!G6 -> Cash | C7: ='Estimate Summary'!B15 -> 158660 | D7: =IFERROR(INDEX(Reference!$HH$2:$HH$1000, MATCH(Builder!G6&"|"&"procedure_ot_charges", Reference!$HA$2:$HA$1000, 0)), 0) -> 154880 | E7: =IFERROR(INDEX(Reference!$HI$2:$HI$1000, MATCH(Builder!G6&"|"&"procedure_ot_charges", Reference!$HA$2:$HA$1000, 0)), 0) -> 159090 | F7: =IFERROR(INDEX(Reference!$HJ$2:$HJ$1000, MATCH(Builder!G6&"|"&"procedure_ot_charges", Reference!$HA$2:$HA$1000, 0)), 0) -> 160140 | G7: =C7-D7 -> 3780 | H7: =C7-E7 -> -430 | I7: =C7-F7 -> -1480 | J7: =IF(AND(OR(C7<D7,C7>F7),ABS(H7)>MAX(5000,0.2*MAX(E7,1))),"Material Gap",IF(C7<D7,"Below Range",IF(C7>F7,"Above Range","Within Range"))) -> Within Range
A8: Bedside Services | B8: =Builder!G6 -> Cash | C8: ='Estimate Summary'!B16 -> 5200 | D8: =IFERROR(INDEX(Reference!$HH$2:$HH$1000, MATCH(Builder!G6&"|"&"bedside_services", Reference!$HA$2:$HA$1000, 0)), 0) -> 4050 | E8: =IFERROR(INDEX(Reference!$HI$2:$HI$1000, MATCH(Builder!G6&"|"&"bedside_services", Reference!$HA$2:$HA$1000, 0)), 0) -> 5090 | F8: =IFERROR(INDEX(Reference!$HJ$2:$HJ$1000, MATCH(Builder!G6&"|"&"bedside_services", Reference!$HA$2:$HA$1000, 0)), 0) -> 6150 | G8: =C8-D8 -> 1150 | H8: =C8-E8 -> 110 | I8: =C8-F8 -> -950 | J8: =IF(AND(OR(C8<D8,C8>F8),ABS(H8)>MAX(5000,0.2*MAX(E8,1))),"Material Gap",IF(C8<D8,"Below Range",IF(C8>F8,"Above Range","Within Range"))) -> Within Range
A9: Pharmacy Total | B9: =Builder!G5 -> Cash | C9: ='Estimate Summary'!B17 -> 189805.04 | D9: =IFERROR(INDEX(Reference!$HH$2:$HH$1000, MATCH(Builder!G5&"|"&"pharmacy_total", Reference!$HA$2:$HA$1000, 0)), 0) -> 182949.11 | E9: =IFERROR(INDEX(Reference!$HI$2:$HI$1000, MATCH(Builder!G5&"|"&"pharmacy_total", Reference!$HA$2:$HA$1000, 0)), 0) -> 189217.61 | F9: =IFERROR(INDEX(Reference!$HJ$2:$HJ$1000, MATCH(Builder!G5&"|"&"pharmacy_total", Reference!$HA$2:$HA$1000, 0)), 0) -> 231144.73 | G9: =C9-D9 -> 6855.9312 | H9: =C9-E9 -> 587.43125 | I9: =C9-F9 -> -41339.696 | J9: =IF(AND(OR(C9<D9,C9>F9),ABS(H9)>MAX(5000,0.2*MAX(E9,1))),"Material Gap",IF(C9<D9,"Below Range",IF(C9>F9,"Above Range","Within Range"))) -> Within Range
A10: IP Drugs | B10: =Builder!G5 -> Cash | C10: =IF(Builder!B4="General",SUMIF('Line Item Detail'!$A$2:$A$73,"IP Drugs & Medications",'Line Item Detail'!$W$2:$W$73),IF(Builder!B4="Twin",SUMIF('Line Item Detail'!$A$2:$A$73,"IP Drugs & Medications",'Line Item Detail'!$X$2:$X$73),SUMIF('Line Item Detail'!$A$2:$A$73,"IP Drugs & Medications",'Line Item Detail'!$Y$2:$Y$73))) -> 8565.9562 | D10: =IFERROR(INDEX(Reference!$HH$2:$HH$1000, MATCH(Builder!G5&"|"&"ip_drugs", Reference!$HA$2:$HA$1000, 0)), 0) -> 7802.505 | E10: =IFERROR(INDEX(Reference!$HI$2:$HI$1000, MATCH(Builder!G5&"|"&"ip_drugs", Reference!$HA$2:$HA$1000, 0)), 0) -> 9060.435 | F10: =IFERROR(INDEX(Reference!$HJ$2:$HJ$1000, MATCH(Builder!G5&"|"&"ip_drugs", Reference!$HA$2:$HA$1000, 0)), 0) -> 10629.097 | G10: =C10-D10 -> 763.45125 | H10: =C10-E10 -> -494.47875 | I10: =C10-F10 -> -2063.1413 | J10: =IF(AND(OR(C10<D10,C10>F10),ABS(H10)>MAX(5000,0.2*MAX(E10,1))),"Material Gap",IF(C10<D10,"Below Range",IF(C10>F10,"Above Range","Within Range"))) -> Within Range
A11: IP Drugs / Day | B11: =Builder!G5 -> Cash | C11: =IF(Builder!G10<=0,0,(IF(Builder!B4="General",SUMIF('Line Item Detail'!$A$2:$A$73,"IP Drugs & Medications",'Line Item Detail'!$W$2:$W$73),IF(Builder!B4="Twin",SUMIF('Line Item Detail'!$A$2:$A$73,"IP Drugs & Medications",'Line Item Detail'!$X$2:$X$73),SUMIF('Line Item Detail'!$A$2:$A$73,"IP Drugs & Medications",'Line Item Detail'!$Y$2:$Y$73))))/Builder!G10) -> 2855.3187 | D11: =IFERROR(INDEX(Reference!$HH$2:$HH$1000, MATCH(Builder!G5&"|"&"ip_drugs_per_day", Reference!$HA$2:$HA$1000, 0)), 0) -> 2380.9425 | E11: =IFERROR(INDEX(Reference!$HI$2:$HI$1000, MATCH(Builder!G5&"|"&"ip_drugs_per_day", Reference!$HA$2:$HA$1000, 0)), 0) -> 2855.32 | F11: =IFERROR(INDEX(Reference!$HJ$2:$HJ$1000, MATCH(Builder!G5&"|"&"ip_drugs_per_day", Reference!$HA$2:$HA$1000, 0)), 0) -> 3198.2575 | G11: =C11-D11 -> 474.37625 | H11: =C11-E11 -> -0.00125 | I11: =C11-F11 -> -342.93875 | J11: =IF(AND(OR(C11<D11,C11>F11),ABS(H11)>MAX(5000,0.2*MAX(E11,1))),"Material Gap",IF(C11<D11,"Below Range",IF(C11>F11,"Above Range","Within Range"))) -> Within Range
A12: IP Consumables | B12: =Builder!G5 -> Cash | C12: =IF(Builder!B4="General",SUMIF('Line Item Detail'!$A$2:$A$73,"IP Consumables",'Line Item Detail'!$W$2:$W$73),IF(Builder!B4="Twin",SUMIF('Line Item Detail'!$A$2:$A$73,"IP Consumables",'Line Item Detail'!$X$2:$X$73),SUMIF('Line Item Detail'!$A$2:$A$73,"IP Consumables",'Line Item Detail'!$Y$2:$Y$73))) -> 10286.485 | D12: =IFERROR(INDEX(Reference!$HH$2:$HH$1000, MATCH(Builder!G5&"|"&"ip_consumables", Reference!$HA$2:$HA$1000, 0)), 0) -> 9677.2125 | E12: =IFERROR(INDEX(Reference!$HI$2:$HI$1000, MATCH(Builder!G5&"|"&"ip_consumables", Reference!$HA$2:$HA$1000, 0)), 0) -> 10711.305 | F12: =IFERROR(INDEX(Reference!$HJ$2:$HJ$1000, MATCH(Builder!G5&"|"&"ip_consumables", Reference!$HA$2:$HA$1000, 0)), 0) -> 11936.618 | G12: =C12-D12 -> 609.2725 | H12: =C12-E12 -> -424.82 | I12: =C12-F12 -> -1650.1325 | J12: =IF(AND(OR(C12<D12,C12>F12),ABS(H12)>MAX(5000,0.2*MAX(E12,1))),"Material Gap",IF(C12<D12,"Below Range",IF(C12>F12,"Above Range","Within Range"))) -> Within Range
A13: IP Consumables / Day | B13: =Builder!G5 -> Cash | C13: =IF(Builder!G10<=0,0,(IF(Builder!B4="General",SUMIF('Line Item Detail'!$A$2:$A$73,"IP Consumables",'Line Item Detail'!$W$2:$W$73),IF(Builder!B4="Twin",SUMIF('Line Item Detail'!$A$2:$A$73,"IP Consumables",'Line Item Detail'!$X$2:$X$73),SUMIF('Line Item Detail'!$A$2:$A$73,"IP Consumables",'Line Item Detail'!$Y$2:$Y$73))))/Builder!G10) -> 3428.8283 | D13: =IFERROR(INDEX(Reference!$HH$2:$HH$1000, MATCH(Builder!G5&"|"&"ip_consumables_per_day", Reference!$HA$2:$HA$1000, 0)), 0) -> 3059.7975 | E13: =IFERROR(INDEX(Reference!$HI$2:$HI$1000, MATCH(Builder!G5&"|"&"ip_consumables_per_day", Reference!$HA$2:$HA$1000, 0)), 0) -> 3428.83 | F13: =IFERROR(INDEX(Reference!$HJ$2:$HJ$1000, MATCH(Builder!G5&"|"&"ip_consumables_per_day", Reference!$HA$2:$HA$1000, 0)), 0) -> 3617.7125 | G13: =C13-D13 -> 369.03083 | H13: =C13-E13 -> -0.0016666667 | I13: =C13-F13 -> -188.88417 | J13: =IF(AND(OR(C13<D13,C13>F13),ABS(H13)>MAX(5000,0.2*MAX(E13,1))),"Material Gap",IF(C13<D13,"Below Range",IF(C13>F13,"Above Range","Within Range"))) -> Within Range
A14: OT Drugs | B14: =Builder!G5 -> Cash | C14: =IF(Builder!B4="General",SUMIF('Line Item Detail'!$A$2:$A$73,"OT Drugs & Medications",'Line Item Detail'!$W$2:$W$73),IF(Builder!B4="Twin",SUMIF('Line Item Detail'!$A$2:$A$73,"OT Drugs & Medications",'Line Item Detail'!$X$2:$X$73),SUMIF('Line Item Detail'!$A$2:$A$73,"OT Drugs & Medications",'Line Item Detail'!$Y$2:$Y$73))) -> 9439.535 | D14: =IFERROR(INDEX(Reference!$HH$2:$HH$1000, MATCH(Builder!G5&"|"&"ot_drugs", Reference!$HA$2:$HA$1000, 0)), 0) -> 8468.8525 | E14: =IFERROR(INDEX(Reference!$HI$2:$HI$1000, MATCH(Builder!G5&"|"&"ot_drugs", Reference!$HA$2:$HA$1000, 0)), 0) -> 9439.535 | F14: =IFERROR(INDEX(Reference!$HJ$2:$HJ$1000, MATCH(Builder!G5&"|"&"ot_drugs", Reference!$HA$2:$HA$1000, 0)), 0) -> 11143.7 | G14: =C14-D14 -> 970.6825 | H14: =C14-E14 -> 0 | I14: =C14-F14 -> -1704.165 | J14: =IF(AND(OR(C14<D14,C14>F14),ABS(H14)>MAX(5000,0.2*MAX(E14,1))),"Material Gap",IF(C14<D14,"Below Range",IF(C14>F14,"Above Range","Within Range"))) -> Within Range
A15: OT Consumables | B15: =Builder!G5 -> Cash | C15: =IF(Builder!B4="General",SUMIF('Line Item Detail'!$A$2:$A$73,"OT Consumables",'Line Item Detail'!$W$2:$W$73),IF(Builder!B4="Twin",SUMIF('Line Item Detail'!$A$2:$A$73,"OT Consumables",'Line Item Detail'!$X$2:$X$73),SUMIF('Line Item Detail'!$A$2:$A$73,"OT Consumables",'Line Item Detail'!$Y$2:$Y$73))) -> 72382.9 | D15: =IFERROR(INDEX(Reference!$HH$2:$HH$1000, MATCH(Builder!G5&"|"&"ot_consumables", Reference!$HA$2:$HA$1000, 0)), 0) -> 66040.54 | E15: =IFERROR(INDEX(Reference!$HI$2:$HI$1000, MATCH(Builder!G5&"|"&"ot_consumables", Reference!$HA$2:$HA$1000, 0)), 0) -> 72382.9 | F15: =IFERROR(INDEX(Reference!$HJ$2:$HJ$1000, MATCH(Builder!G5&"|"&"ot_consumables", Reference!$HA$2:$HA$1000, 0)), 0) -> 107563.63 | G15: =C15-D15 -> 6342.36 | H15: =C15-E15 -> 0 | I15: =C15-F15 -> -35180.73 | J15: =IF(AND(OR(C15<D15,C15>F15),ABS(H15)>MAX(5000,0.2*MAX(E15,1))),"Material Gap",IF(C15<D15,"Below Range",IF(C15>F15,"Above Range","Within Range"))) -> Within Range
A16: Implants | B16: =Builder!G5 -> Cash | C16: =IF(Builder!B4="General",SUMIF('Line Item Detail'!$A$2:$A$73,"Implants",'Line Item Detail'!$W$2:$W$73),IF(Builder!B4="Twin",SUMIF('Line Item Detail'!$A$2:$A$73,"Implants",'Line Item Detail'!$X$2:$X$73),SUMIF('Line Item Detail'!$A$2:$A$73,"Implants",'Line Item Detail'!$Y$2:$Y$73))) -> 89130.16 | D16: =IFERROR(INDEX(Reference!$HH$2:$HH$1000, MATCH(Builder!G5&"|"&"implants", Reference!$HA$2:$HA$1000, 0)), 0) -> 89130.077 | E16: =IFERROR(INDEX(Reference!$HI$2:$HI$1000, MATCH(Builder!G5&"|"&"implants", Reference!$HA$2:$HA$1000, 0)), 0) -> 89130.16 | F16: =IFERROR(INDEX(Reference!$HJ$2:$HJ$1000, MATCH(Builder!G5&"|"&"implants", Reference!$HA$2:$HA$1000, 0)), 0) -> 98838.05 | G16: =C16-D16 -> 0.0825 | H16: =C16-E16 -> 0 | I16: =C16-F16 -> -9707.89 | J16: =IF(AND(OR(C16<D16,C16>F16),ABS(H16)>MAX(5000,0.2*MAX(E16,1))),"Material Gap",IF(C16<D16,"Below Range",IF(C16>F16,"Above Range","Within Range"))) -> Within Range
A17: Drug Administration Charges | B17: =Builder!G5 -> Cash | C17: ='Estimate Summary'!B18 -> 23725.63 | D17: =IFERROR(INDEX(Reference!$HH$2:$HH$1000, MATCH(Builder!G5&"|"&"drug_administration_charges", Reference!$HA$2:$HA$1000, 0)), 0) -> 22868.638 | E17: =IFERROR(INDEX(Reference!$HI$2:$HI$1000, MATCH(Builder!G5&"|"&"drug_administration_charges", Reference!$HA$2:$HA$1000, 0)), 0) -> 23652.2 | F17: =IFERROR(INDEX(Reference!$HJ$2:$HJ$1000, MATCH(Builder!G5&"|"&"drug_administration_charges", Reference!$HA$2:$HA$1000, 0)), 0) -> 28893.092 | G17: =C17-D17 -> 856.99203 | H17: =C17-E17 -> 73.429531 | I17: =C17-F17 -> -5167.463 | J17: =IF(AND(OR(C17<D17,C17>F17),ABS(H17)>MAX(5000,0.2*MAX(E17,1))),"Material Gap",IF(C17<D17,"Below Range",IF(C17>F17,"Above Range","Within Range"))) -> Within Range
A18: Professional Fees (Calculated) | B18: =Builder!G7 -> Cash | C18: ='Estimate Summary'!B19 -> 160001.4 | D18: =IFERROR(INDEX(Reference!$HH$2:$HH$1000, MATCH(Builder!G7&"|"&"professional_fees", Reference!$HA$2:$HA$1000, 0)), 0) -> 96442 | E18: =IFERROR(INDEX(Reference!$HI$2:$HI$1000, MATCH(Builder!G7&"|"&"professional_fees", Reference!$HA$2:$HA$1000, 0)), 0) -> 98192 | F18: =IFERROR(INDEX(Reference!$HJ$2:$HJ$1000, MATCH(Builder!G7&"|"&"professional_fees", Reference!$HA$2:$HA$1000, 0)), 0) -> 99817 | G18: =C18-D18 -> 63559.4 | H18: =C18-E18 -> 61809.4 | I18: =C18-F18 -> 60184.4 | J18: =IF(AND(OR(C18<D18,C18>F18),ABS(H18)>MAX(5000,0.2*MAX(E18,1))),"Material Gap",IF(C18<D18,"Below Range",IF(C18>F18,"Above Range","Within Range"))) -> Material Gap
A19: Professional Fees (Historic Basis P50) | B19: =Builder!G7 -> Cash | C19: ='Estimate Summary'!B22 -> 98192 | D19: =IFERROR(INDEX(Reference!$FE$2:$FE$500, MATCH(Builder!G7, Reference!$FC$2:$FC$500, 0)), 0) -> 96442 | E19: =IFERROR(INDEX(Reference!$FF$2:$FF$500, MATCH(Builder!G7, Reference!$FC$2:$FC$500, 0)), 0) -> 98192 | F19: =IFERROR(INDEX(Reference!$FG$2:$FG$500, MATCH(Builder!G7, Reference!$FC$2:$FC$500, 0)), 0) -> 99817 | G19: =C19-D19 -> 1750 | H19: =C19-E19 -> 0 | I19: =C19-F19 -> -1625 | J19: =IF(AND(OR(C19<D19,C19>F19),ABS(H19)>MAX(5000,0.2*MAX(E19,1))),"Material Gap",IF(C19<D19,"Below Range",IF(C19>F19,"Above Range","Within Range"))) -> Within Range
A20: Grand Total (Calculated PF) | B20: =IF(AND(Builder!G5=Builder!G6,Builder!G6=Builder!G7),Builder!G6,"Component Mix") -> Cash | C20: ='Estimate Summary'!B21 -> 597612.07 | D20: =IF(AND(Builder!G5=Builder!G6,Builder!G6=Builder!G7),IFERROR(INDEX(Reference!$HH$2:$HH$1000, MATCH(Builder!G6&"|"&"total_amount_excluding_food_and_beverage_and_returns_plus_drug_admin", Reference!$HA$2:$HA$1000, 0)), 0),(IFERROR(INDEX(Reference!$HH$2:$HH$1000, MATCH(Builder!G6&"|"&"room_charges", Reference!$HA$2:$HA$1000, 0)), 0) + IFERROR(INDEX(Reference!$HH$2:$HH$1000, MATCH(Builder!G6&"|"&"investigations", Reference!$HA$2:$HA$1000, 0)), 0) + IFERROR(INDEX(Reference!$HH$2:$HH$1000, MATCH(Builder!G6&"|"&"procedure_ot_charges", Reference!$HA$2:$HA$1000, 0)), 0) + IFERROR(INDEX(Reference!$HH$2:$HH$1000, MATCH(Builder!G6&"|"&"bedside_services", Reference!$HA$2:$HA$1000, 0)), 0) + IFERROR(INDEX(Reference!$HH$2:$HH$1000, MATCH(Builder!G5&"|"&"pharmacy_total", Reference!$HA$2:$HA$1000, 0)), 0) + IFERROR(INDEX(Reference!$HH$2:$HH$1000, MATCH(Builder!G5&"|"&"drug_administration_charges", Reference!$HA$2:$HA$1000, 0)), 0) + IFERROR(INDEX(Reference!$HH$2:$HH$1000, MATCH(Builder!G7&"|"&"professional_fees", Reference!$HA$2:$HA$1000, 0)), 0))) -> 520489.65 | E20: =IF(AND(Builder!G5=Builder!G6,Builder!G6=Builder!G7),IFERROR(INDEX(Reference!$HI$2:$HI$1000, MATCH(Builder!G6&"|"&"total_amount_excluding_food_and_beverage_and_returns_plus_drug_admin", Reference!$HA$2:$HA$1000, 0)), 0),(IFERROR(INDEX(Reference!$HI$2:$HI$1000, MATCH(Builder!G6&"|"&"room_charges", Reference!$HA$2:$HA$1000, 0)), 0) + IFERROR(INDEX(Reference!$HI$2:$HI$1000, MATCH(Builder!G6&"|"&"investigations", Reference!$HA$2:$HA$1000, 0)), 0) + IFERROR(INDEX(Reference!$HI$2:$HI$1000, MATCH(Builder!G6&"|"&"procedure_ot_charges", Reference!$HA$2:$HA$1000, 0)), 0) + IFERROR(INDEX(Reference!$HI$2:$HI$1000, MATCH(Builder!G6&"|"&"bedside_services", Reference!$HA$2:$HA$1000, 0)), 0) + IFERROR(INDEX(Reference!$HI$2:$HI$1000, MATCH(Builder!G5&"|"&"pharmacy_total", Reference!$HA$2:$HA$1000, 0)), 0) + IFERROR(INDEX(Reference!$HI$2:$HI$1000, MATCH(Builder!G5&"|"&"drug_administration_charges", Reference!$HA$2:$HA$1000, 0)), 0) + IFERROR(INDEX(Reference!$HI$2:$HI$1000, MATCH(Builder!G7&"|"&"professional_fees", Reference!$HA$2:$HA$1000, 0)), 0))) -> 539491.34 | F20: =IF(AND(Builder!G5=Builder!G6,Builder!G6=Builder!G7),IFERROR(INDEX(Reference!$HJ$2:$HJ$1000, MATCH(Builder!G6&"|"&"total_amount_excluding_food_and_beverage_and_returns_plus_drug_admin", Reference!$HA$2:$HA$1000, 0)), 0),(IFERROR(INDEX(Reference!$HJ$2:$HJ$1000, MATCH(Builder!G6&"|"&"room_charges", Reference!$HA$2:$HA$1000, 0)), 0) + IFERROR(INDEX(Reference!$HJ$2:$HJ$1000, MATCH(Builder!G6&"|"&"investigations", Reference!$HA$2:$HA$1000, 0)), 0) + IFERROR(INDEX(Reference!$HJ$2:$HJ$1000, MATCH(Builder!G6&"|"&"procedure_ot_charges", Reference!$HA$2:$HA$1000, 0)), 0) + IFERROR(INDEX(Reference!$HJ$2:$HJ$1000, MATCH(Builder!G6&"|"&"bedside_services", Reference!$HA$2:$HA$1000, 0)), 0) + IFERROR(INDEX(Reference!$HJ$2:$HJ$1000, MATCH(Builder!G5&"|"&"pharmacy_total", Reference!$HA$2:$HA$1000, 0)), 0) + IFERROR(INDEX(Reference!$HJ$2:$HJ$1000, MATCH(Builder!G5&"|"&"drug_administration_charges", Reference!$HA$2:$HA$1000, 0)), 0) + IFERROR(INDEX(Reference!$HJ$2:$HJ$1000, MATCH(Builder!G7&"|"&"professional_fees", Reference!$HA$2:$HA$1000, 0)), 0))) -> 596680.13 | G20: =C20-D20 -> 77122.413 | H20: =C20-E20 -> 58120.725 | I20: =C20-F20 -> 931.93796 | J20: =IF(AND(OR(C20<D20,C20>F20),ABS(H20)>MAX(5000,0.2*MAX(E20,1))),"Material Gap",IF(C20<D20,"Below Range",IF(C20>F20,"Above Range","Within Range"))) -> Above Range
A21: Grand Total (Historic PF) | B21: =IF(AND(Builder!G5=Builder!G6,Builder!G6=Builder!G7),Builder!G6,"Component Mix + Historic PF") -> Cash | C21: ='Estimate Summary'!B23 -> 535802.67 | D21: =(IFERROR(INDEX(Reference!$HH$2:$HH$1000, MATCH(Builder!G6&"|"&"room_charges", Reference!$HA$2:$HA$1000, 0)), 0) + IFERROR(INDEX(Reference!$HH$2:$HH$1000, MATCH(Builder!G6&"|"&"investigations", Reference!$HA$2:$HA$1000, 0)), 0) + IFERROR(INDEX(Reference!$HH$2:$HH$1000, MATCH(Builder!G6&"|"&"procedure_ot_charges", Reference!$HA$2:$HA$1000, 0)), 0) + IFERROR(INDEX(Reference!$HH$2:$HH$1000, MATCH(Builder!G6&"|"&"bedside_services", Reference!$HA$2:$HA$1000, 0)), 0) + IFERROR(INDEX(Reference!$HH$2:$HH$1000, MATCH(Builder!G5&"|"&"pharmacy_total", Reference!$HA$2:$HA$1000, 0)), 0) + IFERROR(INDEX(Reference!$HH$2:$HH$1000, MATCH(Builder!G5&"|"&"drug_administration_charges", Reference!$HA$2:$HA$1000, 0)), 0) + IFERROR(INDEX(Reference!$FE$2:$FE$500, MATCH(Builder!G7, Reference!$FC$2:$FC$500, 0)), 0)) -> 512127.24 | E21: =(IFERROR(INDEX(Reference!$HI$2:$HI$1000, MATCH(Builder!G6&"|"&"room_charges", Reference!$HA$2:$HA$1000, 0)), 0) + IFERROR(INDEX(Reference!$HI$2:$HI$1000, MATCH(Builder!G6&"|"&"investigations", Reference!$HA$2:$HA$1000, 0)), 0) + IFERROR(INDEX(Reference!$HI$2:$HI$1000, MATCH(Builder!G6&"|"&"procedure_ot_charges", Reference!$HA$2:$HA$1000, 0)), 0) + IFERROR(INDEX(Reference!$HI$2:$HI$1000, MATCH(Builder!G6&"|"&"bedside_services", Reference!$HA$2:$HA$1000, 0)), 0) + IFERROR(INDEX(Reference!$HI$2:$HI$1000, MATCH(Builder!G5&"|"&"pharmacy_total", Reference!$HA$2:$HA$1000, 0)), 0) + IFERROR(INDEX(Reference!$HI$2:$HI$1000, MATCH(Builder!G5&"|"&"drug_administration_charges", Reference!$HA$2:$HA$1000, 0)), 0) + IFERROR(INDEX(Reference!$FF$2:$FF$500, MATCH(Builder!G7, Reference!$FC$2:$FC$500, 0)), 0)) -> 535675.81 | F21: =(IFERROR(INDEX(Reference!$HJ$2:$HJ$1000, MATCH(Builder!G6&"|"&"room_charges", Reference!$HA$2:$HA$1000, 0)), 0) + IFERROR(INDEX(Reference!$HJ$2:$HJ$1000, MATCH(Builder!G6&"|"&"investigations", Reference!$HA$2:$HA$1000, 0)), 0) + IFERROR(INDEX(Reference!$HJ$2:$HJ$1000, MATCH(Builder!G6&"|"&"procedure_ot_charges", Reference!$HA$2:$HA$1000, 0)), 0) + IFERROR(INDEX(Reference!$HJ$2:$HJ$1000, MATCH(Builder!G6&"|"&"bedside_services", Reference!$HA$2:$HA$1000, 0)), 0) + IFERROR(INDEX(Reference!$HJ$2:$HJ$1000, MATCH(Builder!G5&"|"&"pharmacy_total", Reference!$HA$2:$HA$1000, 0)), 0) + IFERROR(INDEX(Reference!$HJ$2:$HJ$1000, MATCH(Builder!G5&"|"&"drug_administration_charges", Reference!$HA$2:$HA$1000, 0)), 0) + IFERROR(INDEX(Reference!$FG$2:$FG$500, MATCH(Builder!G7, Reference!$FC$2:$FC$500, 0)), 0)) -> 598598.32 | G21: =C21-D21 -> 23675.423 | H21: =C21-E21 -> 126.86078 | I21: =C21-F21 -> -62795.659 | J21: =IF(AND(OR(C21<D21,C21>F21),ABS(H21)>MAX(5000,0.2*MAX(E21,1))),"Material Gap",IF(C21<D21,"Below Range",IF(C21>F21,"Above Range","Within Range"))) -> Within Range
A24: Driver | B24: Basis | C24: Selected | D24: Actual P25 | E24: Actual P50 | F24: Actual P75 | G24: Status
A25: LOS | B25: =Builder!G6 -> Cash | C25: =Builder!G10 -> 3 | D25: =IFERROR(INDEX(Reference!$HH$2:$HH$1000, MATCH(Builder!G6&"|"&"los_days", Reference!$HA$2:$HA$1000, 0)), 0) -> 3 | E25: =IFERROR(INDEX(Reference!$HI$2:$HI$1000, MATCH(Builder!G6&"|"&"los_days", Reference!$HA$2:$HA$1000, 0)), 0) -> 3 | F25: =IFERROR(INDEX(Reference!$HJ$2:$HJ$1000, MATCH(Builder!G6&"|"&"los_days", Reference!$HA$2:$HA$1000, 0)), 0) -> 3.75 | G25: =IF(C25<D25,"Below Range",IF(C25>F25,"Above Range","Within Range")) -> Within Range
A26: ICU Days | B26: =Builder!G6 -> Cash | C26: =Builder!G11 -> 2 | D26: =IFERROR(INDEX(Reference!$HH$2:$HH$1000, MATCH(Builder!G6&"|"&"icu_days", Reference!$HA$2:$HA$1000, 0)), 0) -> 2 | E26: =IFERROR(INDEX(Reference!$HI$2:$HI$1000, MATCH(Builder!G6&"|"&"icu_days", Reference!$HA$2:$HA$1000, 0)), 0) -> 2 | F26: =IFERROR(INDEX(Reference!$HJ$2:$HJ$1000, MATCH(Builder!G6&"|"&"icu_days", Reference!$HA$2:$HA$1000, 0)), 0) -> 3 | G26: =IF(C26<D26,"Below Range",IF(C26>F26,"Above Range","Within Range")) -> Within Range
A27: Ward Days | B27: =Builder!G6 -> Cash | C27: =Builder!G12 -> 1 | D27: =IFERROR(INDEX(Reference!$HH$2:$HH$1000, MATCH(Builder!G6&"|"&"ward_days", Reference!$HA$2:$HA$1000, 0)), 0) -> 0.25 | E27: =IFERROR(INDEX(Reference!$HI$2:$HI$1000, MATCH(Builder!G6&"|"&"ward_days", Reference!$HA$2:$HA$1000, 0)), 0) -> 1 | F27: =IFERROR(INDEX(Reference!$HJ$2:$HJ$1000, MATCH(Builder!G6&"|"&"ward_days", Reference!$HA$2:$HA$1000, 0)), 0) -> 1.75 | G27: =IF(C27<D27,"Below Range",IF(C27>F27,"Above Range","Within Range")) -> Within Range
A28: OT Hours | B28: =Builder!G6 -> Cash | C28: =Builder!G13 -> 3 | D28: =IFERROR(INDEX(Reference!$HH$2:$HH$1000, MATCH(Builder!G6&"|"&"ot_hours", Reference!$HA$2:$HA$1000, 0)), 0) -> 2.5 | E28: =IFERROR(INDEX(Reference!$HI$2:$HI$1000, MATCH(Builder!G6&"|"&"ot_hours", Reference!$HA$2:$HA$1000, 0)), 0) -> 3 | F28: =IFERROR(INDEX(Reference!$HJ$2:$HJ$1000, MATCH(Builder!G6&"|"&"ot_hours", Reference!$HA$2:$HA$1000, 0)), 0) -> 3 | G28: =IF(C28<D28,"Below Range",IF(C28>F28,"Above Range","Within Range")) -> Within Range
A31: Component Cohort | B31: Resolved Basis | C31: Cases Used | D31: Cash | E31: GIPSA | F31: Non-GIPSA | G31: Corporate | H31: Scope
A32: Service Actual Cohort | B32: =Builder!G6 -> Cash | C32: =IFERROR(INDEX(Reference!$BA$2:$BA$500, MATCH(Builder!G6, Reference!$AZ$2:$AZ$500, 0)), 0) -> 26 | D32: =IFERROR(INDEX(Reference!$BB$2:$BB$500, MATCH(Builder!G6, Reference!$AZ$2:$AZ$500, 0)), 0) -> 26 | E32: =IFERROR(INDEX(Reference!$BC$2:$BC$500, MATCH(Builder!G6, Reference!$AZ$2:$AZ$500, 0)), 0) -> 0 | F32: =IFERROR(INDEX(Reference!$BD$2:$BD$500, MATCH(Builder!G6, Reference!$AZ$2:$AZ$500, 0)), 0) -> 0 | G32: =IFERROR(INDEX(Reference!$BE$2:$BE$500, MATCH(Builder!G6, Reference!$AZ$2:$AZ$500, 0)), 0) -> 0 | H32: Service buckets and LOS/ICU/ward/OT service-context metrics
A33: Pharmacy Actual Cohort | B33: =Builder!G5 -> Cash | C33: =IFERROR(INDEX(Reference!$BA$2:$BA$500, MATCH(Builder!G5, Reference!$AZ$2:$AZ$500, 0)), 0) -> 26 | D33: =IFERROR(INDEX(Reference!$BB$2:$BB$500, MATCH(Builder!G5, Reference!$AZ$2:$AZ$500, 0)), 0) -> 26 | E33: =IFERROR(INDEX(Reference!$BC$2:$BC$500, MATCH(Builder!G5, Reference!$AZ$2:$AZ$500, 0)), 0) -> 0 | F33: =IFERROR(INDEX(Reference!$BD$2:$BD$500, MATCH(Builder!G5, Reference!$AZ$2:$AZ$500, 0)), 0) -> 0 | G33: =IFERROR(INDEX(Reference!$BE$2:$BE$500, MATCH(Builder!G5, Reference!$AZ$2:$AZ$500, 0)), 0) -> 0 | H33: Pharmacy buckets, per-day pharmacy metrics, and drug administration
A34: PF Actual Cohort | B34: =Builder!G7 -> Cash | C34: =IFERROR(INDEX(Reference!$BA$2:$BA$500, MATCH(Builder!G7, Reference!$AZ$2:$AZ$500, 0)), 0) -> 26 | D34: =IFERROR(INDEX(Reference!$BB$2:$BB$500, MATCH(Builder!G7, Reference!$AZ$2:$AZ$500, 0)), 0) -> 26 | E34: =IFERROR(INDEX(Reference!$BC$2:$BC$500, MATCH(Builder!G7, Reference!$AZ$2:$AZ$500, 0)), 0) -> 0 | F34: =IFERROR(INDEX(Reference!$BD$2:$BD$500, MATCH(Builder!G7, Reference!$AZ$2:$AZ$500, 0)), 0) -> 0 | G34: =IFERROR(INDEX(Reference!$BE$2:$BE$500, MATCH(Builder!G7, Reference!$AZ$2:$AZ$500, 0)), 0) -> 0 | H34: Professional-fee comparison rows, including historic PF reference
A37: Notes
A38: 1. Robotic-charge rows are controlled from the Builder, not from Service Add-Ons. Generic non-robotic variants leave that control blank or No unless the user explicitly includes robotic charges.
A39: 2. OT Consumables show historical P25 / P50 / P75 anchors separately. The applied resolved value defaults to historical P50 and only changes when Advanced Controls selections intentionally change it.
A40: 3. Pharmacy comparison is split into IP drugs, IP consumables, OT drugs, OT consumables, implants, and the rolled-up pharmacy total. LOS-linked pharmacy rows also show per-day comparators.
A41: 4. Drug Administration Charges are shown separately so Bedside Services compares cleanly against historical bedside actuals.
A42: 5. Grand Total (Historic PF) swaps the calculated PF estimate for the selected-basis collectible historical PF reference.
A43: 6. Case counts are shown at the service / pharmacy / PF component-basis level because all rows inside each component share the same resolved historical cohort.

Sheet Advanced Controls
A1: Advanced Controls
A2: Adjust only the OT consumables portion here. Implant overrides are handled on the Implant Selection sheet. Service add-ons are handled on the Service Add-Ons sheet.
A3: OT consumables: benchmark anchors stay fixed at cohort P25 / P50 / P75. The resolved applied value defaults to historical P50 when no shortlist items are selected, then moves by expected-contribution bands from the shortlist below: <=30% stays at P25, 30% to 50% uses P50, and >50% uses P75.
A4: OT Consumables Benchmark | B4: P25 | C4: P50 | D4: P75
B5: =IFERROR(INDEX(Reference!$CD$2:$CD$500, MATCH(Builder!G5, Reference!$AZ$2:$AZ$500, 0)), 0) -> 66040.54 | C5: =IFERROR(INDEX(Reference!$CE$2:$CE$500, MATCH(Builder!G5, Reference!$AZ$2:$AZ$500, 0)), 0) -> 72382.9 | D5: =IFERROR(INDEX(Reference!$CF$2:$CF$500, MATCH(Builder!G5, Reference!$AZ$2:$AZ$500, 0)), 0) -> 107563.63
A6: Resolved OT Consumables | B6: Applied Value | C6: =IF(COUNTIF(H8:H17,"Include")=0,C5,IF(IFERROR(SUMIF(H8:H17,"Include",F8:F17)/SUM(F8:F17),0)<=0.3,B5,IF(IFERROR(SUMIF(H8:H17,"Include",F8:F17)/SUM(F8:F17),0)<=0.5,C5,D5))) -> 72382.9
A7: Item | B7: Typical Qty | C7: Typical Rate | D7: Typical Amount | E7: Presence Rate | F7: Expected Contribution | G7: Cumulative Share | H7: Selected
A8: PURESIGHT ARRAY SET KNEE(4515-70-011-DEPUY) | B8: =IFERROR(INDEX(Reference!$DO$2:$DO$6000, MATCH(Builder!G5&"|"&A8, Reference!$DR$2:$DR$6000, 0)), 2) -> 2 | C8: =IF(B8>0,D8/B8,0) -> 26625 | D8: =IFERROR(INDEX(Reference!$DP$2:$DP$6000, MATCH(Builder!G5&"|"&A8, Reference!$DR$2:$DR$6000, 0)), 53250) -> 53250 | E8: =IFERROR(INDEX(Reference!$DL$2:$DL$6000, MATCH(Builder!G5&"|"&A8, Reference!$DR$2:$DR$6000, 0)), 38.46) -> 38.461538 | F8: =E8*B8*C8/100 -> 20479.95 | G8: =F8/SUM($F$8:$F$17) -> 0.28595734 | H8: Exclude
A9: MAKO DRAPE KIT(PRYMAX) | B9: =IFERROR(INDEX(Reference!$DO$2:$DO$6000, MATCH(Builder!G5&"|"&A9, Reference!$DR$2:$DR$6000, 0)), 1) -> 1 | C9: =IF(B9>0,D9/B9,0) -> 21618.59 | D9: =IFERROR(INDEX(Reference!$DP$2:$DP$6000, MATCH(Builder!G5&"|"&A9, Reference!$DR$2:$DR$6000, 0)), 21618.59) -> 21618.59 | E9: =IFERROR(INDEX(Reference!$DL$2:$DL$6000, MATCH(Builder!G5&"|"&A9, Reference!$DR$2:$DR$6000, 0)), 61.54) -> 61.538462 | F9: =E9*B9*C9/100 -> 13304.08 | G9: =G8+F9/SUM($F$8:$F$17) -> 0.47171949 | H9: Exclude
A10: STERILE DRAPE KIT(4515-70-018-DEPUY) | B10: =IFERROR(INDEX(Reference!$DO$2:$DO$6000, MATCH(Builder!G5&"|"&A10, Reference!$DR$2:$DR$6000, 0)), 1) -> 1 | C10: =IF(B10>0,D10/B10,0) -> 28040 | D10: =IFERROR(INDEX(Reference!$DP$2:$DP$6000, MATCH(Builder!G5&"|"&A10, Reference!$DR$2:$DR$6000, 0)), 28040) -> 28040 | E10: =IFERROR(INDEX(Reference!$DL$2:$DL$6000, MATCH(Builder!G5&"|"&A10, Reference!$DR$2:$DR$6000, 0)), 23.08) -> 23.076923 | F10: =E10*B10*C10/100 -> 6471.632 | G10: =G9+F10/SUM($F$8:$F$17) -> 0.56208156 | H10: Exclude
A11: STERILE DRAPE KIT(4515-70-008-DEPUY) | B11: =IFERROR(INDEX(Reference!$DO$2:$DO$6000, MATCH(Builder!G5&"|"&A11, Reference!$DR$2:$DR$6000, 0)), 1) -> 1 | C11: =IF(B11>0,D11/B11,0) -> 28040 | D11: =IFERROR(INDEX(Reference!$DP$2:$DP$6000, MATCH(Builder!G5&"|"&A11, Reference!$DR$2:$DR$6000, 0)), 28040) -> 28040 | E11: =IFERROR(INDEX(Reference!$DL$2:$DL$6000, MATCH(Builder!G5&"|"&A11, Reference!$DR$2:$DR$6000, 0)), 15.38) -> 15.384615 | F11: =E11*B11*C11/100 -> 4312.552 | G11: =G10+F11/SUM($F$8:$F$17) -> 0.62229684 | H11: Exclude
A12: OSCILLATING SAW BLADE 85MMX19X2MM(4515-70-000-DEPUY) | B12: =IFERROR(INDEX(Reference!$DO$2:$DO$6000, MATCH(Builder!G5&"|"&A12, Reference!$DR$2:$DR$6000, 0)), 1) -> 1 | C12: =IF(B12>0,D12/B12,0) -> 30093 | D12: =IFERROR(INDEX(Reference!$DP$2:$DP$6000, MATCH(Builder!G5&"|"&A12, Reference!$DR$2:$DR$6000, 0)), 30093) -> 30093 | E12: =IFERROR(INDEX(Reference!$DL$2:$DL$6000, MATCH(Builder!G5&"|"&A12, Reference!$DR$2:$DR$6000, 0)), 11.54) -> 11.538462 | F12: =E12*B12*C12/100 -> 3472.7322 | G12: =G11+F12/SUM($F$8:$F$17) -> 0.67078588 | H12: Exclude
A13: MICS SAGITTAL BLADE STANDARD(116170-STRYKER) | B13: =IFERROR(INDEX(Reference!$DO$2:$DO$6000, MATCH(Builder!G5&"|"&A13, Reference!$DR$2:$DR$6000, 0)), 3) -> 3 | C13: =IF(B13>0,D13/B13,0) -> 3526 | D13: =IFERROR(INDEX(Reference!$DP$2:$DP$6000, MATCH(Builder!G5&"|"&A13, Reference!$DR$2:$DR$6000, 0)), 10578) -> 10578 | E13: =IFERROR(INDEX(Reference!$DL$2:$DL$6000, MATCH(Builder!G5&"|"&A13, Reference!$DR$2:$DR$6000, 0)), 26.92) -> 26.923077 | F13: =E13*B13*C13/100 -> 2847.5976 | G13: =G12+F13/SUM($F$8:$F$17) -> 0.7105463 | H13: Exclude
A14: STRATAFIX 1 SXPP1A203(ETHICON) | B14: =IFERROR(INDEX(Reference!$DO$2:$DO$6000, MATCH(Builder!G5&"|"&A14, Reference!$DR$2:$DR$6000, 0)), 1) -> 1 | C14: =IF(B14>0,D14/B14,0) -> 3760 | D14: =IFERROR(INDEX(Reference!$DP$2:$DP$6000, MATCH(Builder!G5&"|"&A14, Reference!$DR$2:$DR$6000, 0)), 3760) -> 3760 | E14: =IFERROR(INDEX(Reference!$DL$2:$DL$6000, MATCH(Builder!G5&"|"&A14, Reference!$DR$2:$DR$6000, 0)), 61.54) -> 61.538462 | F14: =E14*B14*C14/100 -> 2313.904 | G14: =G13+F14/SUM($F$8:$F$17) -> 0.74285487 | H14: Exclude
A15: 116171 MICS SAGITTAL BLADE NARROW | B15: =IFERROR(INDEX(Reference!$DO$2:$DO$6000, MATCH(Builder!G5&"|"&A15, Reference!$DR$2:$DR$6000, 0)), 3) -> 3 | C15: =IF(B15>0,D15/B15,0) -> 3333.3333 | D15: =IFERROR(INDEX(Reference!$DP$2:$DP$6000, MATCH(Builder!G5&"|"&A15, Reference!$DR$2:$DR$6000, 0)), 9999.99) -> 10000 | E15: =IFERROR(INDEX(Reference!$DL$2:$DL$6000, MATCH(Builder!G5&"|"&A15, Reference!$DR$2:$DR$6000, 0)), 15.38) -> 15.384615 | F15: =E15*B15*C15/100 -> 1538 | G15: =G14+F15/SUM($F$8:$F$17) -> 0.76432965 | H15: Exclude
A16: 107120 MAKO VIZADISCS | B16: =IFERROR(INDEX(Reference!$DO$2:$DO$6000, MATCH(Builder!G5&"|"&A16, Reference!$DR$2:$DR$6000, 0)), 1) -> 1 | C16: =IF(B16>0,D16/B16,0) -> 4218.6 | D16: =IFERROR(INDEX(Reference!$DP$2:$DP$6000, MATCH(Builder!G5&"|"&A16, Reference!$DR$2:$DR$6000, 0)), 4218.6) -> 4218.6 | E16: =IFERROR(INDEX(Reference!$DL$2:$DL$6000, MATCH(Builder!G5&"|"&A16, Reference!$DR$2:$DR$6000, 0)), 26.92) -> 26.923077 | F16: =E16*B16*C16/100 -> 1135.6471 | G16: =G15+F16/SUM($F$8:$F$17) -> 0.78018646 | H16: Exclude
A17: CORK SCREW FT-2 5.5MM WITH NEEDLE 16.3MM(AR-1928SNF-2-ARTHREX) | B17: =IFERROR(INDEX(Reference!$DO$2:$DO$6000, MATCH(Builder!G5&"|"&A17, Reference!$DR$2:$DR$6000, 0)), 1) -> 1 | C17: =IF(B17>0,D17/B17,0) -> 27280 | D17: =IFERROR(INDEX(Reference!$DP$2:$DP$6000, MATCH(Builder!G5&"|"&A17, Reference!$DR$2:$DR$6000, 0)), 27280) -> 27280 | E17: =IFERROR(INDEX(Reference!$DL$2:$DL$6000, MATCH(Builder!G5&"|"&A17, Reference!$DR$2:$DR$6000, 0)), 3.85) -> 3.8461538 | F17: =E17*B17*C17/100 -> 1050.28 | G17: =G16+F17/SUM($F$8:$F$17) -> 0.7948513 | H17: Exclude

Sheet Service Add-Ons
